2025-02-28 12:23:20,620 - INFO - Making predictions for 1578 samples...
2025-02-28 12:23:21,700 - INFO - Predictions saved to all_predict_01.csv
2025-02-28 12:23:21,702 - INFO - Top 30 predictions saved to top_30_predictions_01.csv
2025-02-28 12:23:22,545 - INFO - Making predictions for 1578 samples...
2025-02-28 12:23:22,928 - INFO - Predictions saved to all_predict_01.csv
2025-02-28 12:23:22,929 - INFO - Top 30 predictions saved to top_30_predictions_01.csv
2025-02-28 12:30:41,740 - INFO - Making predictions for 1578 samples...
2025-02-28 12:30:42,332 - INFO - Predictions saved to all_predict_01.csv
2025-02-28 12:30:42,333 - INFO - Top 30 predictions saved to top_30_predictions_01.csv
2025-02-28 12:30:43,117 - INFO - Making predictions for 1578 samples...
2025-02-28 12:30:43,391 - INFO - Predictions saved to all_predict_01.csv
2025-02-28 12:30:43,392 - INFO - Top 30 predictions saved to top_30_predictions_01.csv
2025-02-28 12:34:00,540 - ERROR - Internal Server Error: /dj_api/get_all_rnas/
Traceback (most recent call last):
  File "D:\MyAnaconda\envs\torchpy39\lib\site-packages\django\core\handlers\exception.py", line 55, in inner
    response = get_response(request)
  File "D:\MyAnaconda\envs\torchpy39\lib\site-packages\django\core\handlers\base.py", line 197, in _get_response
    response = wrapped_callback(request, *callback_args, **callback_kwargs)
  File "D:\MyGitProjects\dj_mda\dj_api\views.py", line 463, in get_all_rnas
    test_data = TestbedDataset(root='dj_api/data', dataset=f'last/_mytest{str_i}', xd=test_drugs,
  File "D:\MyGitProjects\dj_mda\dj_api\utils\utils.py", line 26, in __init__
    self.process(xd, xt, y, z, smile_graph)
  File "D:\MyGitProjects\dj_mda\dj_api\utils\utils.py", line 97, in process
    data, slices = self.collate(data_list)
  File "D:\MyAnaconda\envs\torchpy39\lib\site-packages\torch_geometric\data\in_memory_dataset.py", line 156, in collate
    data_list[0].__class__,
IndexError: list index out of range
